<?xml version="1.0"?>
<robot name="wheeltec_robot">

  <!-- ────────── Chassis ────────── -->
  <link name="base_link">
    <visual>
      <!-- chassis geometric centre -->
      <origin xyz="0 0 0.025" rpy="0 0 0"/>
      <geometry>
        <box size="1.04 0.845 0.05"/>
      </geometry>
      <material name="white">
        <color rgba="1 1 1 1"/>
      </material>
    </visual>
    <collision>
      <origin xyz="0 0 0.025" rpy="0 0 0"/>
      <geometry>
        <box size="1.04 0.845 0.05"/>
      </geometry>
    </collision>
  </link>

  <!-- ────────── Rear drive wheels ────────── -->
  <joint name="left_wheel_joint" type="continuous">
    <origin xyz="0 0.08 0.0325" rpy="1.57 0 0"/>
    <parent link="base_link"/>
    <child  link="left_wheel_link"/>
    <axis  xyz="0 1 0"/>
  </joint>

  <link name="left_wheel_link">
    <visual>
      <origin xyz="0 0 0" rpy="0 0 0"/>
      <geometry>
        <cylinder radius="0.0325" length="0.025"/>
      </geometry>
      <material name="black">
        <color rgba="0 0 0 1"/>
      </material>
    </visual>
  </link>

  <joint name="right_wheel_joint" type="continuous">
    <origin xyz="0 -0.08 0.0325" rpy="1.57 0 0"/>
    <parent link="base_link"/>
    <child  link="right_wheel_link"/>
    <axis  xyz="0 1 0"/>
  </joint>

  <link name="right_wheel_link">
    <visual>
      <origin xyz="0 0 0" rpy="0 0 0"/>
      <geometry>
        <cylinder radius="0.0325" length="0.025"/>
      </geometry>
      <material name="black">
        <color rgba="0 0 0 1"/>
      </material>
    </visual>
  </link>

  <!-- ────────── Front casters (dual) ────────── -->
  <!-- left caster swivel -->
  <joint name="front_left_caster_swivel_joint" type="continuous">
    <origin xyz="0.15 0.08 0.0325" rpy="0 0 0"/>
    <parent link="base_link"/>
    <child  link="front_left_caster_link"/>
    <axis  xyz="0 0 1"/>
  </joint>

  <link name="front_left_caster_link">
    <!-- optional slim plate for swivel frame -->
  </link>

  <!-- left caster wheel spin -->
  <joint name="front_left_caster_wheel_joint" type="continuous">
    <origin xyz="0 0 0" rpy="1.57 0 0"/>
    <parent link="front_left_caster_link"/>
    <child  link="front_left_wheel_link"/>
    <axis  xyz="0 1 0"/>
  </joint>

  <link name="front_left_wheel_link">
    <visual>
      <origin xyz="0 0 0" rpy="0 0 0"/>
      <geometry>
        <cylinder radius="0.0325" length="0.02"/>
      </geometry>
      <material name="black">
        <color rgba="0 0 0 1"/>
      </material>
    </visual>
  </link>

  <!-- right caster swivel -->
  <joint name="front_right_caster_swivel_joint" type="continuous">
    <origin xyz="0.15 -0.08 0.0325" rpy="0 0 0"/>
    <parent link="base_link"/>
    <child  link="front_right_caster_link"/>
    <axis  xyz="0 0 1"/>
  </joint>

  <link name="front_right_caster_link">
  </link>

  <!-- right caster wheel spin -->
  <joint name="front_right_caster_wheel_joint" type="continuous">
    <origin xyz="0 0 0" rpy="1.57 0 0"/>
    <parent link="front_right_caster_link"/>
    <child  link="front_right_wheel_link"/>
    <axis  xyz="0 1 0"/>
  </joint>

  <link name="front_right_wheel_link">
    <visual>
      <origin xyz="0 0 0" rpy="0 0 0"/>
      <geometry>
        <cylinder radius="0.0325" length="0.02"/>
      </geometry>
      <material name="black">
        <color rgba="0 0 0 1"/>
      </material>
    </visual>
  </link>

</robot>
